first test message...
index first test message...
first test message...
index first test message...
first test message...
index first test message...
初始化日志配置成功...
初始化日志配置成功...
index first test message...
初始化日志配置成功...
初始化日志配置成功...
An exception happenning: 31
Exception on / [GET]
Traceback (most recent call last):
  File "C:\Users\xeekseven\AppData\Local\Programs\Python\Python37\lib\site-packages\flask\app.py", line 2292, in wsgi_app
    response = self.full_dispatch_request()
  File "C:\Users\xeekseven\AppData\Local\Programs\Python\Python37\lib\site-packages\flask\app.py", line 1816, in full_dispatch_request
    return self.finalize_request(rv)
  File "C:\Users\xeekseven\AppData\Local\Programs\Python\Python37\lib\site-packages\flask\app.py", line 1831, in finalize_request
    response = self.make_response(rv)
  File "C:\Users\xeekseven\AppData\Local\Programs\Python\Python37\lib\site-packages\flask\app.py", line 1957, in make_response
    'The view function did not return a valid response. The'
TypeError: The view function did not return a valid response. The function either returned None or ended without a return statement.
2018-11-08 22:50:48,261 INFO: 初始化日志配置成功... [in D:\python\xeekwebsite_flask\xeekwebsite_server\LogFactory.py:33]
