2018-11-08 22:02:18,180 ERROR: first test message... [in D:\python\xeekwebsite_flask\xeekwebsite_server\__init__.py:54]
2018-11-08 22:03:00,645 ERROR: first test message... [in D:\python\xeekwebsite_flask\xeekwebsite_server\__init__.py:54]
2018-11-08 22:03:14,046 ERROR: first test message... [in D:\python\xeekwebsite_flask\xeekwebsite_server\__init__.py:54]
2018-11-08 22:03:15,338 ERROR: Exception on / [GET] [in C:\Users\xeekseven\AppData\Local\Programs\Python\Python37\lib\site-packages\flask\app.py:1761]
Traceback (most recent call last):
  File "C:\Users\xeekseven\AppData\Local\Programs\Python\Python37\lib\site-packages\flask\app.py", line 2292, in wsgi_app
    response = self.full_dispatch_request()
  File "C:\Users\xeekseven\AppData\Local\Programs\Python\Python37\lib\site-packages\flask\app.py", line 1816, in full_dispatch_request
    return self.finalize_request(rv)
  File "C:\Users\xeekseven\AppData\Local\Programs\Python\Python37\lib\site-packages\flask\app.py", line 1831, in finalize_request
    response = self.make_response(rv)
  File "C:\Users\xeekseven\AppData\Local\Programs\Python\Python37\lib\site-packages\flask\app.py", line 1957, in make_response
    'The view function did not return a valid response. The'
TypeError: The view function did not return a valid response. The function either returned None or ended without a return statement.
2018-11-08 22:03:50,406 ERROR: first test message... [in D:\python\xeekwebsite_flask\xeekwebsite_server\__init__.py:54]
2018-11-08 22:03:51,818 ERROR: Exception on / [GET] [in C:\Users\xeekseven\AppData\Local\Programs\Python\Python37\lib\site-packages\flask\app.py:1761]
Traceback (most recent call last):
  File "C:\Users\xeekseven\AppData\Local\Programs\Python\Python37\lib\site-packages\flask\app.py", line 2292, in wsgi_app
    response = self.full_dispatch_request()
  File "C:\Users\xeekseven\AppData\Local\Programs\Python\Python37\lib\site-packages\flask\app.py", line 1816, in full_dispatch_request
    return self.finalize_request(rv)
  File "C:\Users\xeekseven\AppData\Local\Programs\Python\Python37\lib\site-packages\flask\app.py", line 1831, in finalize_request
    response = self.make_response(rv)
  File "C:\Users\xeekseven\AppData\Local\Programs\Python\Python37\lib\site-packages\flask\app.py", line 1957, in make_response
    'The view function did not return a valid response. The'
TypeError: The view function did not return a valid response. The function either returned None or ended without a return statement.
2018-11-08 22:04:00,617 ERROR: first test message... [in D:\python\xeekwebsite_flask\xeekwebsite_server\__init__.py:54]
2018-11-08 22:04:01,856 ERROR: Exception on / [GET] [in C:\Users\xeekseven\AppData\Local\Programs\Python\Python37\lib\site-packages\flask\app.py:1761]
Traceback (most recent call last):
  File "C:\Users\xeekseven\AppData\Local\Programs\Python\Python37\lib\site-packages\flask\app.py", line 2292, in wsgi_app
    response = self.full_dispatch_request()
  File "C:\Users\xeekseven\AppData\Local\Programs\Python\Python37\lib\site-packages\flask\app.py", line 1815, in full_dispatch_request
    rv = self.handle_user_exception(e)
  File "C:\Users\xeekseven\AppData\Local\Programs\Python\Python37\lib\site-packages\flask\app.py", line 1718, in handle_user_exception
    reraise(exc_type, exc_value, tb)
  File "C:\Users\xeekseven\AppData\Local\Programs\Python\Python37\lib\site-packages\flask\_compat.py", line 35, in reraise
    raise value
  File "C:\Users\xeekseven\AppData\Local\Programs\Python\Python37\lib\site-packages\flask\app.py", line 1813, in full_dispatch_request
    rv = self.dispatch_request()
  File "C:\Users\xeekseven\AppData\Local\Programs\Python\Python37\lib\site-packages\flask\app.py", line 1799, in dispatch_request
    return self.view_functions[rule.endpoint](**req.view_args)
  File "D:\python\xeekwebsite_flask\xeekwebsite_server\view\home.py", line 23, in index
    app.logger.error('index first test message...')
NameError: name 'app' is not defined
2018-11-08 22:04:48,206 ERROR: first test message... [in D:\python\xeekwebsite_flask\xeekwebsite_server\__init__.py:56]
2018-11-08 22:04:49,322 ERROR: Exception on / [GET] [in C:\Users\xeekseven\AppData\Local\Programs\Python\Python37\lib\site-packages\flask\app.py:1761]
Traceback (most recent call last):
  File "C:\Users\xeekseven\AppData\Local\Programs\Python\Python37\lib\site-packages\flask\app.py", line 2292, in wsgi_app
    response = self.full_dispatch_request()
  File "C:\Users\xeekseven\AppData\Local\Programs\Python\Python37\lib\site-packages\flask\app.py", line 1815, in full_dispatch_request
    rv = self.handle_user_exception(e)
  File "C:\Users\xeekseven\AppData\Local\Programs\Python\Python37\lib\site-packages\flask\app.py", line 1718, in handle_user_exception
    reraise(exc_type, exc_value, tb)
  File "C:\Users\xeekseven\AppData\Local\Programs\Python\Python37\lib\site-packages\flask\_compat.py", line 35, in reraise
    raise value
  File "C:\Users\xeekseven\AppData\Local\Programs\Python\Python37\lib\site-packages\flask\app.py", line 1813, in full_dispatch_request
    rv = self.dispatch_request()
  File "C:\Users\xeekseven\AppData\Local\Programs\Python\Python37\lib\site-packages\flask\app.py", line 1799, in dispatch_request
    return self.view_functions[rule.endpoint](**req.view_args)
  File "D:\python\xeekwebsite_flask\xeekwebsite_server\view\home.py", line 23, in index
    app.logger.error('index first test message...')
NameError: name 'app' is not defined
2018-11-08 22:05:21,627 ERROR: first test message... [in D:\python\xeekwebsite_flask\xeekwebsite_server\__init__.py:56]
2018-11-08 22:15:05,813 ERROR: first test message... [in D:\python\xeekwebsite_flask\xeekwebsite_server\__init__.py:54]
2018-11-08 22:16:00,075 ERROR: first test message... [in D:\python\xeekwebsite_flask\xeekwebsite_server\__init__.py:54]
2018-11-08 22:18:39,149 ERROR: first test message... [in D:\python\xeekwebsite_flask\xeekwebsite_server\__init__.py:55]
2018-11-08 22:18:41,128 ERROR: Exception on / [GET] [in C:\Users\xeekseven\AppData\Local\Programs\Python\Python37\lib\site-packages\flask\app.py:1761]
Traceback (most recent call last):
  File "C:\Users\xeekseven\AppData\Local\Programs\Python\Python37\lib\site-packages\flask\app.py", line 2292, in wsgi_app
    response = self.full_dispatch_request()
  File "C:\Users\xeekseven\AppData\Local\Programs\Python\Python37\lib\site-packages\flask\app.py", line 1815, in full_dispatch_request
    rv = self.handle_user_exception(e)
  File "C:\Users\xeekseven\AppData\Local\Programs\Python\Python37\lib\site-packages\flask\app.py", line 1718, in handle_user_exception
    reraise(exc_type, exc_value, tb)
  File "C:\Users\xeekseven\AppData\Local\Programs\Python\Python37\lib\site-packages\flask\_compat.py", line 35, in reraise
    raise value
  File "C:\Users\xeekseven\AppData\Local\Programs\Python\Python37\lib\site-packages\flask\app.py", line 1813, in full_dispatch_request
    rv = self.dispatch_request()
  File "C:\Users\xeekseven\AppData\Local\Programs\Python\Python37\lib\site-packages\flask\app.py", line 1799, in dispatch_request
    return self.view_functions[rule.endpoint](**req.view_args)
  File "D:\python\xeekwebsite_flask\xeekwebsite_server\view\home.py", line 24, in index
    app.logger.error('index first test message...')
NameError: name 'app' is not defined
2018-11-08 22:28:08,149 ERROR: first test message... [in D:\python\xeekwebsite_flask\xeekwebsite_server\__init__.py:55]
2018-11-08 22:28:09,861 ERROR: index first test message... [in D:\python\xeekwebsite_flask\xeekwebsite_server\view\home.py:22]
